<?xml version="1.0"?>
<!-- =================================================================================== -->
<!-- |    This document was autogenerated by xacro from
/home/youssef/hosbot_wp/src/robot_urdf/urdf/robot.urdf.xacro | -->
<!-- |    EDITING THIS FILE BY HAND IS NOT RECOMMENDED                                 | -->
<!-- =================================================================================== -->
<robot name="hosbot">
  <!-- COLORS-->
  <material name="colors_gray">
    <color rgba="0.66 0.66 0.66 1.0" />
  </material>
  <material name="colors_black">
    <color rgba="0.0 0.0 0.0 1.0" />
  </material>
  <link name="base_link" />
  <!-- SHAPE-->
  <link name="robot_base_link">
    <visual>
      <geometry>
        <cylinder length="0.25" radius="0.2" />
      </geometry>
      <material name="colors_gray" />
    </visual>
  </link>
  <!-- JOINT-->
  <joint name="robot_base_joint" type="fixed">
    <parent link="base_link" />
    <child link="robot_base_link" />
    <origin xyz="0.0 0.0 0.14100000000000001" />
  </joint>
  <!-- SHAPE-->
  <link name="left_wheel">
    <visual>
      <geometry>
        <cylinder length="0.01" radius="0.016" />
      </geometry>
      <material name="colors_gray" />
    </visual>
    <collision>
      <geometry>
        <cylinder length="0.01" radius="0.016" />
      </geometry>
    </collision>
    <inertial>
      <mass value="0.1" />
      <inertia ixx="1e-4" ixy="0" ixz="0" iyy="1e-4" iyz="0" izz="1e-4" />
    </inertial>
  </link>
  <!-- Joint-->
  <joint name="left_wheel_joint" type="continuous">
    <parent link="robot_base_link" />
    <child link="left_wheel" />
    <origin rpy="1.5708 0 0" xyz="0 0.15 -0.125 " />
    <!-- -0.061-->
    <axis xyz="0 0 1" />
  </joint>
  <!-- SHAPE-->
  <link name="right_wheel">
    <visual>
      <geometry>
        <cylinder length="0.01" radius="0.016" />
      </geometry>
      <material name="colors_gray" />
    </visual>
    <collision>
      <geometry>
        <cylinder length="0.01" radius="0.016" />
      </geometry>
    </collision>
    <inertial>
      <mass value="0.1" />
      <inertia ixx="1e-4" ixy="0" ixz="0" iyy="1e-4" iyz="0" izz="1e-4" />
    </inertial>
  </link>
  <!-- Joint-->
  <joint name="right_wheel_joint" type="continuous">
    <parent link="robot_base_link" />
    <child link="right_wheel" />
    <origin rpy="1.5708 0 0" xyz="0 -0.15 -0.125 " />
    <!-- -0.061-->
    <axis xyz="0 0 1" />
  </joint>
  <link name="free_wheel_1_link">
    <visual>
      <geometry>
        <sphere radius="0.016" />
      </geometry>
    </visual>
    <collision>
      <geometry>
        <sphere radius="0.016" />
      </geometry>
    </collision>
    <inertial>
      <mass value="0.01" />
      <inertia ixx="1e-5" ixy="0" ixz="0" iyy="1e-5" iyz="0" izz="1e-5" />
    </inertial>
  </link>
  <joint name="free_wheel_1_joint" type="fixed">
    <parent link="robot_base_link" />
    <child link="free_wheel_1_link" />
    <origin xyz=" 0.1228   0.0860 -0.125" />
    <!--  rpy="0 0 0.9599"-->
  </joint>
  <link name="free_wheel_2_link">
    <visual>
      <geometry>
        <sphere radius="0.016" />
      </geometry>
    </visual>
    <collision>
      <geometry>
        <sphere radius="0.016" />
      </geometry>
    </collision>
    <inertial>
      <mass value="0.01" />
      <inertia ixx="1e-5" ixy="0" ixz="0" iyy="1e-5" iyz="0" izz="1e-5" />
    </inertial>
  </link>
  <joint name="free_wheel_2_joint" type="fixed">
    <parent link="robot_base_link" />
    <child link="free_wheel_2_link" />
    <origin xyz=" 0.1228  -0.0860 -0.125" />
    <!--  rpy="0 0 0.9599"-->
  </joint>
  <link name="free_wheel_3_link">
    <visual>
      <geometry>
        <sphere radius="0.016" />
      </geometry>
    </visual>
    <collision>
      <geometry>
        <sphere radius="0.016" />
      </geometry>
    </collision>
    <inertial>
      <mass value="0.01" />
      <inertia ixx="1e-5" ixy="0" ixz="0" iyy="1e-5" iyz="0" izz="1e-5" />
    </inertial>
  </link>
  <joint name="free_wheel_3_joint" type="fixed">
    <parent link="robot_base_link" />
    <child link="free_wheel_3_link" />
    <origin xyz="-0.1228   0.0860 -0.125" />
    <!--  rpy="0 0 0.9599"-->
  </joint>
  <link name="free_wheel_4_link">
    <visual>
      <geometry>
        <sphere radius="0.016" />
      </geometry>
    </visual>
    <collision>
      <geometry>
        <sphere radius="0.016" />
      </geometry>
    </collision>
    <inertial>
      <mass value="0.01" />
      <inertia ixx="1e-5" ixy="0" ixz="0" iyy="1e-5" iyz="0" izz="1e-5" />
    </inertial>
  </link>
  <joint name="free_wheel_4_joint" type="fixed">
    <parent link="robot_base_link" />
    <child link="free_wheel_4_link" />
    <origin xyz="-0.1228  -0.0860 -0.125" />
    <!--  rpy="0 0 0.9599"-->
  </joint>
  <!--  -145' -->
  <link name="lidar">
    <visual>
      <geometry>
        <cylinder length="0.01" radius="0.019" />
      </geometry>
      <material name="colors_gray" />
    </visual>
  </link>
  <joint name="lidar_joint" type="fixed">
    <parent link="robot_base_link" />
    <child link="lidar" />
    <origin xyz="0.12 0.0 0.13" />
  </joint>
  <link name="ultrasound_chassis_support_link">
    <visual>
      <geometry>
        <box size="0.01 0.399 0.07" />
      </geometry>
      <material name="colors_gray" />
    </visual>
  </link>
  <joint name="lidar_background_joint" type="fixed">
    <parent link="robot_base_link" />
    <child link="ultrasound_chassis_support_link" />
    <origin xyz="0.0 0.0 0.16" />
  </joint>
  <!-- BODY -->
  <link name="ultrasound_chassis_link">
    <visual>
      <geometry>
        <cylinder length="0.065" radius="0.2" />
      </geometry>
      <material name="colors_gray" />
    </visual>
  </link>
  <joint name="ultrasound_chassis_joint" type="fixed">
    <parent link="ultrasound_chassis_support_link" />
    <child link="ultrasound_chassis_link" />
    <origin xyz="0.0 0.0 0.0675" />
  </joint>
  <link name="ultrasound_1_link">
    <visual>
      <geometry>
        <cylinder length="0.01" radius="0.01" />
      </geometry>
      <material name="colors_black" />
    </visual>
  </link>
  <joint name="ultrasound_1_joint" type="fixed">
    <parent link="ultrasound_chassis_link" />
    <child link="ultrasound_1_link" />
    <origin rpy="0 1.5708 0" xyz="0.1951 0 0" />
  </joint>
  <link name="ultrasound_2_link">
    <visual>
      <geometry>
        <cylinder length="0.01" radius="0.01" />
      </geometry>
      <material name="colors_black" />
    </visual>
  </link>
  <joint name="ultrasound_2_joint" type="fixed">
    <parent link="ultrasound_chassis_link" />
    <child link="ultrasound_2_link" />
    <origin rpy="-0.698 1.5708 0" xyz="0.1494 0.1254 0" />
  </joint>
  <link name="ultrasound_3_link">
    <visual>
      <geometry>
        <cylinder length="0.01" radius="0.01" />
      </geometry>
      <material name="colors_black" />
    </visual>
  </link>
  <joint name="ultrasound_3_joint" type="fixed">
    <parent link="ultrasound_chassis_link" />
    <child link="ultrasound_3_link" />
    <origin rpy="0.698 1.5708 0" xyz="0.1494 -0.1254 0" />
  </joint>
</robot>