<?xml version="1.0"?>

<robot xmlns:xacro="http://www.ros.org/wiki/xacro" name="wheels">

    <!-- PROPERTIES-->
    <!-- <xacro:include filename="properties.xacro" /> -->
    <xacro:property name="wheel_width" value="0.01" />
    <xacro:property name="wheel_radius" value="0.016" />

    <xacro:macro name="wheel" params="name y">

        <!-- SHAPE-->
        <link name="${name}">
            <visual>
                <geometry>
                    <cylinder radius="${wheel_radius}" length="${wheel_width}" />
                </geometry>
                <material name="colors_gray" />
            </visual>

            <collision>
                <geometry>
                    <cylinder radius="${wheel_radius}" length="${wheel_width}" />
                </geometry>
            </collision>

            <inertial>
                <mass value="0.1" />
                <inertia ixx="1e-4" ixy="0" ixz="0" iyy="1e-4" iyz="0" izz="1e-4" />
            </inertial>
        </link>

        <!-- Joint-->
        <joint name="${name}_joint" type="continuous">
            <parent link="robot_base_link" />
            <child link="${name}" />
            <origin xyz="0 ${y} -${robot_base_hight /2} " rpy="1.5708 0 0" /> <!-- -0.061-->
            <axis xyz="0 0 1" />
        </joint>

    </xacro:macro>
</robot>